# 예외
## 예외
**예외**Exception란 프로그램을 만든 프로그래머가 상정한 정상의 범주에서 벗어난 경우를 처리하기 위한 방법이다.
자바는 예상치 못한 오류를 어떤 식으로 처리하는지 이전의 계산기 코드로 알아보도록 한다.<br>
아래는 기존 계산기 코드에서 더하기(`sum`)와 평균(`avg`)메소드를 제거하고, 나누기 메소드를 추가한 코드이다.
```
class Calculator {
	int left, right;
	public void setOprands (int left, int right) {
		this.left = left;
		this.right = right;
	}
	public void divide() {
		System.out.println("계산 결과는 ");
		System.out.println(this.left/this.right);
		System.out.println("입니다.");
	}
}
public class CalculatorDemo {
	public static void main(String[] args) {
		Calculator c1 = new Calculator();
		c1.setOprands(10, 0);
		c1.divide();
	}

}
```
위 코드는 에러가 발생한다. 
```
계산결과는 Exception in thread "main" java.lang.ArithmeticException: / by zero
    at org.opentutorials.javatutorials.exception.Calculator.divide(CalculatorDemo.java:10)
    at org.opentutorials.javatutorials.exception.CalculatorDemo.main(CalculatorDemo.java:18)
 ```
에러 내역을 확인해보면 `System.out.print("계산결과는 ")`까지는 코드가 진행되는 것을 알 수 있다. 
```
계산결과는 Exception in thread "main" java.lang.ArithmeticException: / by zero
```
그 이후 에러가 발생한 이유는 10을 0으로 나누려 했기 때문이다.
```
    at org.opentutorials.javatutorials.exception.Calculator.divide(CalculatorDemo.java:10)
    at org.opentutorials.javatutorials.exception.CalculatorDemo.main(CalculatorDemo.java:18)
```
이 에러 메세지는 오류가 발생한 순서를 추적하고 있다. 아래쪽이 문제의 로직을 호출한 부분이고 위쪽이 문제의 원인이다.
이처럼 에러 메세지는 시스템에서 어떤 오류가 발생했을 때 그 오류를 이해하고 파악하는 데 큰 도움이 된다.
<br>
<br>
에러를 피해 다시 코드를 작성해 보았다.
```java
class Calculator {
	int left, right;
	public void setOprands (int left, int right) {
		this.left = left;
		this.right = right;
	}
	public void divide() {
		try {
			System.out.println("계산 결과 ");
			System.out.println(this.left/this.right);
			System.out.println("입니다.");
			System.out.println("");

		} catch(Exception e) {
			System.out.println("에러가 발생했습니다 : " + e.getMessage());
			System.out.println("");
		}
	}
}
public class CalculatorDemo {
	public static void main(String[] args) {
		Calculator c1 = new Calculator();
		c1.setOprands(10, 0);
		c1.divide();
		
		Calculator c2 = new Calculator();
		c2.setOprands(10, 5);
		c2.divide();
	}


}

```
결과
```
계산 결과 
에러가 발생했습니다 : / by zero

계산 결과 
2
입니다.
```
try...catch 문을 사용해 기존의 에러를 해결한 모습이다.
## try...catch
**try...catch**는 예외에서 핵심적인 역할을 담당하는 문법적 요소이다. 형식을 살펴보자.<br>
```
try {
    에러 발생이 예상되는 로직
    } catch ( 예외 클래스의 인스턴스 ) {
    예외가 발생했을 때 실행하는 로직
    }
```
**try** 안에는 예외 상황이 발생할 것으로 예상되는 로직을 위치시킨다. 
예제에서는 사용자가 setOprands의 두 번째 인자로 숫자 0을 입력했을 때 문제가 발생할 수 있음을 예상할 수 있다. 
그래서 이 로직을 try 구문으로 감싼 것이다.<br>
<br>
catch 안에는 예외가 발생했을 때 '뒷수습'을 하기 위한 로직이 위치한다. 
예제의 실행결과 중 0으로 나눈 부분을 다시 한번 살펴보면 다음과 같다.
```
계산 결과 
에러가 발생했습니다 : / by zero
```
이것은 `System.out.print(this.left/this.right)` 라인을 실행 도중
에러가 발생하면서 try 내의 실행이 중단되고 catch 구문 안의 내용이 실행되었음을 의미한다.

### 예외 클래스와 인스턴스
```
} catch(Exception e){
    System.out.println("오류가 발생했습니다 : "+e.getMessage());
}
```
`e`는 변수이다. 이 변수 앞의 `Exception`은 변수의 데이터타입이 'Excepition'이라는 뜻이다. 
`Excepition`은 자바에서 기본적으로 제공하는 클래스로 `java.lang`에 소속되어 있다. 
예외가 발생하면 자바는 메소드를 호출하듯 `catch`를 호출하면서 그 인자로 `Exception` 클래스의 인스턴스를 전달하는 것이다.<br>
<br>
`e.getMessage()`는 자바가 전달한 인스턴스의 메소드 중 getMessage를 호출하는 코드인데, 
getMessage는 오류의 원인을 사람이 이해하기 쉬운 형태로 return하도록 약속되어 있다.<br>

## 뒷수습의 방법
예외의 핵심은 '뒷수습'이다. 하지만 이를 제대로 해내는 건 대단히 어렵다. 여기서는 자바에서 기본적으로 제공하는 방법만 알아보자.
```java
class Calculator {
	int left, right;
	public void setOprands (int left, int right) {
		this.left = left;
		this.right = right;
	}
	public void divide() {
		try {
			System.out.println("계산 결과 ");
			System.out.println(this.left/this.right);
			System.out.println("입니다.");
			System.out.println("");

		} catch(Exception e) {
			System.out.println("\n\ne.getMessage()\n" + e.getMessage());
			System.out.println("\n\ne.toString()\n" + e.toString());
			System.out.println("\n\ne.printStackTrace()");
			e.printStackTrace();
		}
	}
}
public class CalculatorDemo {
	public static void main(String[] args) {
		Calculator c1 = new Calculator();
		c1.setOprands(10, 0);
		c1.divide();
		
	}
}
```
결과는 다음과 같다
```
계산 결과 


e.getMessage()
/ by zero


e.toString()
java.lang.ArithmeticException: / by zero


e.printStackTrace()
java.lang.ArithmeticException: / by zero
	at org.opentutorials.javatutorials.exception.Calculator.divide(CalculatorDemo.java:11)
	at org.opentutorials.javatutorials.exception.CalculatorDemo.main(CalculatorDemo.java:27)
```
### e.getMessage()
오류에 대한 기본적인 내용을 출력해준다. 상세하지 않다.<br>
### e.toString()
`e.toString()`을 호출한 결과는 `ava.lang.ArithmeticException: / by zero`이다. 
`e.toString()`은 `e.e.getMessage()`보다 더 자세한 예외 정보를 제공한다.
`java.lang.ArithmeticException:`은 은 발생한 예외가 어떤 예외에 해당하는지에 대한 정보인데,
`ArithmeticException`은 현재 수학적 계산 과정에서 발생한 예외상황임을 의미한다(0으로 나누려 했기에).
### e.printStackTrace()
이 메소드를 호출하면 리턴값 없이 메소드가 내부적으로 예외 결과를 화면에 출력한다. 
위 코드에서 보는 것과 같이 셋 중 가장 자세한 예외 정보를 제공한다.

## 다양한 예외들
이번에는 좀 더 다양한 예외 상황을 처리하는 방법이다.
```java
class A{
    private int[] arr = new int[3];
    A(){
        arr[0]=0;
        arr[1]=10;
        arr[2]=20;
    }
    public void z(int first, int second){
        System.out.println(arr[first] / arr[second]);
    }
}
 
public class ExceptionDemo1 {
    public static void main(String[] args) {
        A a = new A();
        a.z(10, 1);
    }
}
```
위 코드에서는 아래와 같은 에러가 발생한다.
```
Exception in thread "main" java.lang.ArrayIndexOutOfBoundsException: 10
    at org.opentutorials.javatutorials.exception.A.z(ExceptionDemo1.java:11)
    at org.opentutorials.javatutorials.exception.ExceptionDemo1.main(ExceptionDemo1.java:18)
```
이유를 따져보자.<br>
`private int[] arr = new int[3]`라인에서 보듯 배열 `arr`은 3개의 값을 담을 수 있다. 
하지만 `a.z(10, 1)` `System.out.println(arr[first] / arr[second])`로 범위를 벗어난 10번째 인덱스를 호출하기에 에러가 발생한다. 
존재하지 않는 값을 가져오려고 시도하고 있기 때문에 자바에서 `ArrayIndexOutOfBoundsException`을 발생시킨 것이다. <br>
<br>
마지막 인스턴스 부분의 코드를 변경하여 다른 에러도 발생시켜 보았다.
```java
(...)
public class ExceptionDemo1 {
    public static void main(String[] args) {
        A a = new A();
        a.z(1, 0);
    }
}
```
실행하면 아래와 같은 에러가 발생한다.
```
Exception in thread "main" java.lang.ArithmeticException: / by zero
    at org.opentutorials.javatutorials.exception.A.z(ExceptionDemo1.java:11)
    at org.opentutorials.javatutorials.exception.ExceptionDemo1.main(ExceptionDemo1.java:18)
```
메소드 `z`에서 내부적으로 '10 나누기 0'을 실행하는데, 0으로 값을 나누는 것을 불가능하기 때문에 자바는 `ArithmeticException`을 발생시킨다. <br>
이처럼 같은 로직이어도 상황에 따라 다른 예외가 발생할 수 있다. 이런 경우는 어떻게 예외를 처리해야 할까?
```java
class A {
	private int[] arr = new int[3];
	A() {
		arr[0] = 0;
		arr[1] = 10;
		arr[2] = 20;
	}
	public void z ( int first, int second) {
		try {
			System.out.println(arr[first] / arr[second]);
		} catch(ArrayIndexOutOfBoundsException e) {
			System.out.println("ArrayIndexOutOfBoundsException");
		} catch(ArithmeticException e) {
			System.out.println("ArithmeticException");
		} catch(Exception e) {
			System.out.println("Exception");
		}
	}
}
public class ExceptionDemo1 {
	public static void main(String[] args) {
		A a = new A();
		a.z(10, 0);
		a.z(1, 0);
		a.z(2, 1);
	}

}
```
결과는 다음과 같다.
```java
ArrayIndexOutOfBoundsException
ArithmeticException
2
```
위 코드는 다중 catch를 보여준다. 조건문의 else if 처럼 여러개의 catch를 하나의 try 구문에서 사용할 수 있고,
이를 통해 보다 간편하게 다양한 상황에 대응할 수 있다.

## finally
finally는 try 구문에서 예외가 발생하는 것과 상관없이 언제나 실행되는 로직이다.
```
try {
    에러 발생이 예상되는 로직
    } catch ( 예외 클래스의 인스턴스 ) {
    예외가 발생했을 때 실행하는 로직
    } finally {
    예외여부와 관계없이 실행하는 로직
    }
```
코드를 변경하여 알아보자.
```java
(...)
	public void z ( int first, int second) {
		try {
			System.out.println(arr[first] / arr[second]);
		} catch(ArrayIndexOutOfBoundsException e) {
			System.out.println("ArrayIndexOutOfBoundsException");
		} catch(ArithmeticException e) {
			System.out.println("ArithmeticException");
		} catch(Exception e) {
			System.out.println("Exception");
		} finally {
			System.out.println("finally");
		}
	}
}
(...)
```
실행결과는 다음과 같다.
```
ArrayIndexOutOfBoundsException
finally
ArithmeticException
finally
2
finally
```
예외와 상관없이 try 내의 구문이 실행되면 finally가 실행되고 있다. 
예외처리를 '뒷수습'에 비유한다면, finally는 수습 후 '마무리, 혹은 '뒷정리'에 해당한다고 볼 수 있겠다. 




